<?xml version="1.0"?>
<robot xmlns:xacro="http://www.ros.org/wiki/xacro" name="locus_robot">

  <xacro:property name="chassis_length" value="0.8"/>
  <xacro:property name="chassis_width"  value="0.6"/>
  <xacro:property name="chassis_height" value="0.3"/>
  <xacro:property name="chassis_mass"   value="4.0"/>

  <xacro:property name="wheel_radius"   value="0.06"/>
  <xacro:property name="wheel_width"    value="0.06"/>
  <xacro:property name="wheel_mass"     value="0.175"/>

  <xacro:property name="track_width"    value="0.5"/>
  <xacro:property name="wheel_base"     value="0.6"/>

  <xacro:macro name="box_inertia" params="m w h d">
    <inertial>
      <origin xyz="0 0 0" rpy="0 0 0"/>
      <mass value="${m}"/>
      <inertia ixx="${(m/12)*(h*h + d*d)}" ixy="0" ixz="0"
               iyy="${(m/12)*(w*w + d*d)}" iyz="0"
               izz="${(m/12)*(w*w + h*h)}"/>
    </inertial>
  </xacro:macro>

  <xacro:macro name="cylinder_inertia" params="m r h">
    <inertial>
      <origin xyz="0 0 0" rpy="0 0 0"/>
      <mass value="${m}"/>
      <inertia ixx="${(m/12)*(3*r*r + h*h)}" ixy="0" ixz="0"
               iyy="${(m/12)*(3*r*r + h*h)}" iyz="0"
               izz="${(m/2)*r*r}"/>
    </inertial>
  </xacro:macro>

  <material name="blue"><color rgba="0.1 0.4 0.8 1"/></material>
  <material name="black"><color rgba="0 0 0 1"/></material>
  <material name="grey"><color rgba="0.5 0.5 0.5 1"/></material>

  <link name="base_footprint"/>

  <joint name="base_footprint_joint" type="fixed">
    <parent link="base_footprint"/>
    <child  link="base_link"/>
    <origin xyz="0 0 ${wheel_radius}"/>
  </joint>

  <link name="base_link">
    <visual>
      <origin xyz="0 0 ${chassis_height/2}"/>
      <geometry><box size="${chassis_length} ${chassis_width} ${chassis_height}"/></geometry>
      <material name="blue"/>
    </visual>
    <collision>
      <origin xyz="0 0 ${chassis_height/2}"/>
      <geometry><box size="${chassis_length} ${chassis_width} ${chassis_height}"/></geometry>
    </collision>
    <xacro:box_inertia m="${chassis_mass}" w="${chassis_width}" h="${chassis_height}" d="${chassis_length}"/>
  </link>

  <xacro:macro name="wheel" params="name x y">
    <link name="${name}_wheel">
      <visual>
        <origin rpy="${pi/2} 0 0"/>
        <geometry><cylinder radius="${wheel_radius}" length="${wheel_width}"/></geometry>
        <material name="black"/>
      </visual>
      <collision>
        <origin rpy="${pi/2} 0 0"/>
        <geometry><cylinder radius="${wheel_radius}" length="${wheel_width}"/></geometry>
      </collision>
      <xacro:cylinder_inertia m="${wheel_mass}" r="${wheel_radius}" h="${wheel_width}"/>
    </link>
    <joint name="${name}_wheel_joint" type="continuous">
      <parent link="base_link"/>
      <child  link="${name}_wheel"/>
      <origin xyz="${x} ${y} ${-wheel_radius}"/>
      <axis xyz="0 1 0"/>
    </joint>
  </xacro:macro>

  <xacro:wheel name="front_left"  x="${wheel_base/2}"  y="${track_width/2}"/>
  <xacro:wheel name="front_right" x="${wheel_base/2}"  y="${-track_width/2}"/>
  <xacro:wheel name="rear_left"   x="${-wheel_base/2}" y="${track_width/2}"/>
  <xacro:wheel name="rear_right"  x="${-wheel_base/2}" y="${-track_width/2}"/>

  <!-- lidar_link: no collision block so laser rays are not blocked by own geometry -->
  <link name="lidar_link">
    <visual><geometry><cylinder radius="0.05" length="0.05"/></geometry><material name="grey"/></visual>
    <inertial><mass value="0.2"/><inertia ixx="0.001" ixy="0" ixz="0" iyy="0.001" iyz="0" izz="0.001"/></inertial>
  </link>
  <joint name="lidar_joint" type="fixed">
    <parent link="base_link"/>
    <child  link="lidar_link"/>
    <origin xyz="0 0 ${chassis_height + 0.1}" rpy="0 0 0"/>
  </joint>

  <!-- imu_link: no collision block, it is a sensor not a physical obstacle -->
  <link name="imu_link">
    <visual><geometry><box size="0.03 0.03 0.01"/></geometry><material name="grey"/></visual>
    <inertial><mass value="0.02"/><inertia ixx="0.0001" ixy="0" ixz="0" iyy="0.0001" iyz="0" izz="0.0001"/></inertial>
  </link>
  <joint name="imu_joint" type="fixed">
    <parent link="base_link"/>
    <child  link="imu_link"/>
    <origin xyz="0 0 ${chassis_height/2}" rpy="0 0 0"/>
  </joint>

<!-- ============================================================
       ROS2 CONTROL
       Defines the hardware interface and joints that ros2_control
       will manage. In simulation, GazeboSystem talks to Gazebo.
       On real hardware, you replace GazeboSystem with your
       actual motor driver interface.
       ============================================================ -->
  <ros2_control name="locus_robot" type="system">

    <hardware>
      <!-- Simulation hardware interface — talks to Gazebo Harmonic -->
      <plugin>gz_ros2_control/GazeboSimSystem</plugin>
    </hardware>

    <!-- Each wheel joint needs velocity command and state interfaces -->
    <joint name="front_left_wheel_joint">
      <command_interface name="velocity"/>
      <state_interface name="velocity"/>
      <state_interface name="position"/>
    </joint>

    <joint name="front_right_wheel_joint">
      <command_interface name="velocity"/>
      <state_interface name="velocity"/>
      <state_interface name="position"/>
    </joint>

    <joint name="rear_left_wheel_joint">
      <command_interface name="velocity"/>
      <state_interface name="velocity"/>
      <state_interface name="position"/>
    </joint>

    <joint name="rear_right_wheel_joint">
      <command_interface name="velocity"/>
      <state_interface name="velocity"/>
      <state_interface name="position"/>
    </joint>

  </ros2_control>

  <xacro:include filename="$(find locus_description)/urdf/locus_gazebo.xacro"/>

</robot>
